<?xml version="1.0" encoding="utf-8"?>
<!-- This URDF was automatically created by SolidWorks to URDF Exporter! Originally created by Stephen Brawner (brawner@gmail.com) 
     Commit Version: 1.6.0-1-g15f4949  Build Version: 1.6.7594.29634
     For more information, please see http://wiki.ros.org/sw_urdf_exporter -->
<robot
  name="humanURDF">
  <link
    name="base_link">
    <inertial>
      <origin
        xyz="-0.147380279946403 4.09803356324946E-18 -0.183688926406411"
        rpy="0 0 0" />
      <mass
        value="21.1782903595475" />
      <inertia
        ixx="0.314167968794279"
        ixy="-1.57515840667926E-17"
        ixz="-0.00152092128911395"
        iyy="0.500403583328166"
        iyz="-1.31389883452136E-09"
        izz="0.26323408507304" />
    </inertial>
    <visual>
      <origin
        xyz="0 0 0"
        rpy="0 0 0" />
      <geometry>
        <mesh
          filename="package://humanURDF/meshes/base_link.STL" />
      </geometry>
      <material
        name="">
        <color
          rgba="0.749019607843137 0.749019607843137 0.749019607843137 1" />
      </material>
    </visual>
    <collision>
      <origin
        xyz="0 0 0"
        rpy="0 0 0" />
      <geometry>
        <mesh
          filename="package://humanURDF/meshes/base_link.STL" />
      </geometry>
    </collision>
  </link>
  <link
    name="brazo_link">
    <inertial>
      <origin
        xyz="0.0501986538571646 -0.0977300384950257 0.00176645149512299"
        rpy="0 0 0" />
      <mass
        value="1.97753622371589" />
      <inertia
        ixx="0.0157981761158755"
        ixy="-2.6966120279389E-05"
        ixz="-1.59507260844094E-06"
        iyy="0.00211316900882633"
        iyz="0.000112507197754403"
        izz="0.0158808780480386" />
    </inertial>
    <visual>
      <origin
        xyz="0 0 0"
        rpy="0 0 0" />
      <geometry>
        <mesh
          filename="package://humanURDF/meshes/brazo_link.STL" />
      </geometry>
      <material
        name="">
        <color
          rgba="0.749019607843137 0.749019607843137 0.749019607843137 1" />
      </material>
    </visual>
    <collision>
      <origin
        xyz="0 0 0"
        rpy="0 0 0" />
      <geometry>
        <mesh
          filename="package://humanURDF/meshes/brazo_link.STL" />
      </geometry>
    </collision>
  </link>
  <joint
    name="brazo_joint"
    type="continuous">
    <origin
      xyz="0.049284658059624 0 -0.0640498975439988"
      rpy="0 0 0" />
    <parent
      link="base_link" />
    <child
      link="brazo_link" />
    <axis
      xyz="-1 0 0" />
  </joint>
  <link
    name="antebrazo_link">
    <inertial>
      <origin
        xyz="0.0436519728379535 -0.0874871117981463 -0.00130930871816355"
        rpy="0 0 0" />
      <mass
        value="1.00812958445801" />
      <inertia
        ixx="0.00754277884263541"
        ixy="-0.000153723622133985"
        ixz="-3.53540231519263E-06"
        iyy="0.000601748852949274"
        iyz="-0.0001831113070396"
        izz="0.00751716655766249" />
    </inertial>
    <visual>
      <origin
        xyz="0 0 0"
        rpy="0 0 0" />
      <geometry>
        <mesh
          filename="package://humanURDF/meshes/antebrazo_link.STL" />
      </geometry>
      <material
        name="">
        <color
          rgba="0.749019607843137 0.749019607843137 0.749019607843137 1" />
      </material>
    </visual>
    <collision>
      <origin
        xyz="0 0 0"
        rpy="0 0 0" />
      <geometry>
        <mesh
          filename="package://humanURDF/meshes/antebrazo_link.STL" />
      </geometry>
    </collision>
  </link>
  <joint
    name="antebrazo_joint"
    type="continuous">
    <origin
      xyz="0.0893153894032891 -0.197868013214099 0.00343687354219388"
      rpy="0 0 0" />
    <parent
      link="brazo_link" />
    <child
      link="antebrazo_link" />
    <axis
      xyz="-0.999701434390246 0.011113823153 -0.0217606298854042" />
  </joint>
</robot>