<?xml version="1.0" encoding="utf-8"?>
<!-- This URDF was automatically created by SolidWorks to URDF Exporter! Originally created by Stephen Brawner (brawner@gmail.com) 
     Commit Version: 1.6.0-1-g15f4949  Build Version: 1.6.7594.29634
     For more information, please see http://wiki.ros.org/sw_urdf_exporter -->
<robot
  name="human_v2">
  <link
    name="base_link">
    <inertial>
      <origin
        xyz="0.0002987 0 0.20019"
        rpy="0 0 0" />
      <mass
        value="21.148" />
      <inertia
        ixx="0.31372"
        ixy="-6.6938E-18"
        ixz="-0.00075664"
        iyy="0.49862"
        iyz="-5.7126E-10"
        izz="0.26189" />
    </inertial>
    <visual>
      <origin
        xyz="0 0 0"
        rpy="0 0 0" />
      <geometry>
        <mesh
          filename="package://human_v2/meshes/base_link.STL" />
      </geometry>
      <material
        name="">
        <color
          rgba="0.74902 0.74902 0.74902 1" />
      </material>
    </visual>
    <collision>
      <origin
        xyz="0 0 0"
        rpy="0 0 0" />
      <geometry>
        <mesh
          filename="package://human_v2/meshes/base_link.STL" />
      </geometry>
    </collision>
  </link>
  <link
    name="Shoulder_Link">
    <inertial>
      <origin
        xyz="0.028934 -3.3332E-07 4.0773E-07"
        rpy="0 0 0" />
      <mass
        value="0.039246" />
      <inertia
        ixx="2.5628E-05"
        ixy="4.8361E-10"
        ixz="-6.0372E-10"
        iyy="3.3171E-05"
        iyz="-1.2792E-09"
        izz="2.6396E-05" />
    </inertial>
    <visual>
      <origin
        xyz="0 0 0"
        rpy="0 0 0" />
      <geometry>
        <mesh
          filename="package://human_v2/meshes/Shoulder_Link.STL" />
      </geometry>
      <material
        name="">
        <color
          rgba="0.79216 0.81961 0.93333 1" />
      </material>
    </visual>
    <collision>
      <origin
        xyz="0 0 0"
        rpy="0 0 0" />
      <geometry>
        <mesh
          filename="package://human_v2/meshes/Shoulder_Link.STL" />
      </geometry>
    </collision>
  </link>
  <joint
    name="shoulder_Joint"
    type="continuous">
    <origin
      xyz="0.18 0 0.32"
      rpy="0 0 0" />
    <parent
      link="base_link" />
    <child
      link="Shoulder_Link" />
    <axis
      xyz="1 0 0" />
  </joint>
  <link
    name="Arm_Link">
    <inertial>
      <origin
        xyz="0.001504 -0.21367 2.1137E-05"
        rpy="0 0 0" />
      <mass
        value="2.065" />
      <inertia
        ixx="0.015833"
        ixy="0.00012729"
        ixz="-2.4985E-07"
        iyy="0.0021521"
        iyz="1.4532E-06"
        izz="0.015925" />
    </inertial>
    <visual>
      <origin
        xyz="0 0 0"
        rpy="0 0 0" />
      <geometry>
        <mesh
          filename="package://human_v2/meshes/Arm_Link.STL" />
      </geometry>
      <material
        name="">
        <color
          rgba="0.79216 0.81961 0.93333 1" />
      </material>
    </visual>
    <collision>
      <origin
        xyz="0 0 0"
        rpy="0 0 0" />
      <geometry>
        <mesh
          filename="package://human_v2/meshes/Arm_Link.STL" />
      </geometry>
    </collision>
  </link>
  <joint
    name="Arm_Joint"
    type="continuous">
    <origin
      xyz="0.07 0 0"
      rpy="0 0 0" />
    <parent
      link="Shoulder_Link" />
    <child
      link="Arm_Link" />
    <axis
      xyz="0 7.9554E-05 1" />
  </joint>
  <link
    name="Forearm_Link">
    <inertial>
      <origin
        xyz="0.043007 -0.087026 0.00061887"
        rpy="0 0 0" />
      <mass
        value="1.0081" />
      <inertia
        ixx="0.0075453"
        ixy="-8.0779E-05"
        ixz="5.269E-07"
        iyy="0.00059467"
        iyz="3.9526E-05"
        izz="0.0075218" />
    </inertial>
    <visual>
      <origin
        xyz="0 0 0"
        rpy="0 0 0" />
      <geometry>
        <mesh
          filename="package://human_v2/meshes/Forearm_Link.STL" />
      </geometry>
      <material
        name="">
        <color
          rgba="0.74902 0.74902 0.74902 1" />
      </material>
    </visual>
    <collision>
      <origin
        xyz="0 0 0"
        rpy="0 0 0" />
      <geometry>
        <mesh
          filename="package://human_v2/meshes/Forearm_Link.STL" />
      </geometry>
    </collision>
  </link>
  <joint
    name="Forearm_Joint"
    type="continuous">
    <origin
      xyz="0.043395 -0.322 0.00014624"
      rpy="0 0 0" />
    <parent
      link="Arm_Link" />
    <child
      link="Forearm_Link" />
    <axis
      xyz="-1 2.0809E-05 -0.0027793" />
  </joint>
</robot>